Workbook

Sheet dropDetailed
A1: 掉落ID | C1: 权重_道具ID | D1: 道具1 | E1: 权重 | F1: 道具ID | G1: 道具数量 | H1: 道具名字 | I1: 道具2 | J1: 权重 | K1: 道具ID | L1: 道具数量 | M1: 道具名字
A2: int | C2: list<list<int>{_}>{|}
A3: id | C3: detailedDropItem
A5: 20000000 | B5: 1金币 | C5: 1000_1990000_1 | D5: 1000_1990000_1 | E5: 1000 | F5: 1990000 | G5: 1 | H5: 金币
A6: 20000001 | B6: 5000_10000随机金币 | C6: 900_1990000_10000|900_1990000_5000 | D6: 900_1990000_5000 | E6: 900 | F6: 1990000 | G6: 5000 | H6: 金币 | I6: 900_1990000_10000 | J6: 900 | K6: 1990000 | L6: 10000 | M6: 金币
A7: 20000002 | B7: 10000_50000随机金币 | C7: 900_1990000_50000|900_1990000_10000 | D7: 900_1990000_10000 | E7: 900 | F7: 1990000 | G7: 10000 | H7: 金币 | I7: 900_1990000_50000 | J7: 900 | K7: 1990000 | L7: 50000 | M7: 金币
A8: 20000003 | B8: 50000_100000随机金币 | C8: 900_1990000_100000|900_1990000_50000 | D8: 900_1990000_50000 | E8: 900 | F8: 1990000 | G8: 50000 | H8: 金币 | I8: 900_1990000_100000 | J8: 900 | K8: 1990000 | L8: 100000 | M8: 金币
A9: 20000004 | B9: 100000_500000随机金币 | C9: 900_1990000_500000|900_1990000_100000 | D9: 900_1990000_100000 | E9: 900 | F9: 1990000 | G9: 100000 | H9: 金币 | I9: 900_1990000_500000 | J9: 900 | K9: 1990000 | L9: 500000 | M9: 金币
A10: 20000008 | B10: 拼图碎片包1 | C10: 400_1200101_1|400_1200102_1|400_1200103_1|400_1200121_1|400_1200122_1|400_1200123_1|400_1200141_1|400_1200142_1|400_1200143_1|400_1200161_1|400_1200162_1|400_1200163_1|400_1200181_1|400_1200182_1|400_1200183_1|400_1200201_1|400_1200202_1|400_1200203_1|400_1200221_1|400_1200222_1|400_1200223_1|400_1200241_1|400_1200242_1|400_1200243_1
A11: 20000009 | B11: 拼图碎片包2 | C11: 400_1200101_1|400_1200102_1|400_1200103_1|400_1200121_1|400_1200122_1|400_1200123_1|400_1200141_1|400_1200142_1|400_1200143_1|400_1200161_1|400_1200162_1|400_1200163_1|400_1200181_1|400_1200182_1|400_1200183_1|400_1200201_1|400_1200202_1|400_1200203_1|400_1200221_1|400_1200222_1|400_1200223_1|400_1200241_1|400_1200242_1|400_1200243_1
A12: 20000010 | B12: 拼图碎片包3 | C12: 400_1200101_1|400_1200102_1|400_1200103_1|400_1200121_1|400_1200122_1|400_1200123_1|400_1200141_1|400_1200142_1|400_1200143_1|400_1200161_1|400_1200162_1|400_1200163_1|400_1200181_1|400_1200182_1|400_1200183_1|400_1200201_1
A13: 20000011 | B13: 拼图碎片包4 | C13: 400_1200101_1|400_1200102_1|400_1200103_1|400_1200121_1|400_1200122_1|400_1200123_1|400_1200141_1|400_1200142_1|400_1200143_1|400_1200161_1|400_1200162_1|400_1200163_1|400_1200181_1|400_1200182_1|400_1200183_1|400_1200201_1
A14: 20000012 | B14: 拼图碎片包5 | C14: 400_1200101_1|400_1200102_1|400_1200103_1|400_1200121_1|400_1200122_1|400_1200123_1|400_1200141_1|400_1200142_1|400_1200143_1|400_1200161_1|400_1200162_1|400_1200163_1|400_1200181_1|400_1200182_1|400_1200183_1|400_1200201_1
A15: 20000021 | B15: 刮刮卡 | C15: 1000_1022502_1
A16: 20010040 | B16: 赌场材料-40级 | C16: 3790_1023001_1|1061_1023101_1|352_1023201_1|189_1023301_1|107_1023401_1
A17: 20010050 | B17: 赌场材料-50级 | C17: 3772_1023001_1|1057_1023101_1|352_1023201_1|189_1023301_1|107_1023401_1
A18: 20010060 | B18: 赌场材料-60级 | C18: 2512_1023001_1|1686_1023001_5|702_1023101_1|505_1023101_5|235_1023201_1|196_1023201_5|231_1023301_1|71_1023401_1|56_1023401_5
A19: 20010070 | B19: 赌场材料-70级 | C19: 682_1023001_1|1834_1023001_5|191_1023101_1|550_1023101_5|64_1023201_1|212_1023201_5|33_1023301_1|163_1023301_5|18_1023401_1|60_1023401_5
A20: 20010080 | B20: 赌场材料-80级 | C20: 940_1023001_1|1260_1023001_5|1260_1023001_17|263_1023101_1|378_1023101_5|378_1023101_16|86_1023201_1|145_1023201_5|145_1023201_15|48_1023301_1|111_1023301_5|88_1023301_15|27_1023401_1|41_1023401_5|41_1023401_15
A21: 20010090 | B21: 赌场材料-90级 | C21: 458_1023001_5|1830_1023001_17|136_1023101_5|548_1023101_16|53_1023201_5|212_1023201_15|43_1023301_5|129_1023301_15|16_1023401_5|60_1023401_15
... A39: 20020021 | B39: 1星材料包-40 | C39: 6566_1023001_40|1928_1023101_40|750_1023201_40|503_1023301_40|251_1023401_40

Sheet Sheet1
A1: 20010040 | B1: 2500_1023001_1|833_1023101_1|208_1023201_1|104_1023301_1|52_1023401_1 | C1: =_xlfn.XLOOKUP(A1,$A$16:$A$222,$L$16:$L$222,B1) -> 2500_1023001_1|833_1023101_1|208_1023201_1|104_1023301_1|52_1023401_1
A2: 20010050 | B2: 2500_1023001_1|833_1023101_1|208_1023201_1|104_1023301_1|52_1023401_1 | C2: =_xlfn.XLOOKUP(A2,$A$16:$A$222,$L$16:$L$222,B2) -> 2500_1023001_1|833_1023101_1|208_1023201_1|104_1023301_1|52_1023401_1
A3: 20010060 | B3: 2500_1023001_1|1667_1023002_1|833_1023101_1|556_1023102_1|208_1023201_1|139_1023202_1|104_1023301_1|69_1023302_1|52_1023401_1|35_1023402_1 | C3: =_xlfn.XLOOKUP(A3,$A$16:$A$222,$L$16:$L$222,B3) -> 2500_1023001_1|833_1023001_2|833_1023101_1|278_1023101_2|208_1023201_1|69_1023201_2|104_1023301_1|34_1023301_2|52_1023401_1|17_1023401_2
A4: 20010070 | B4: 2500_1023001_1|1667_1023002_1|833_1023101_1|556_1023102_1|208_1023201_1|139_1023202_1|104_1023301_1|69_1023302_1|52_1023401_1|35_1023402_1 | C4: =_xlfn.XLOOKUP(A4,$A$16:$A$222,$L$16:$L$222,B4) -> 2500_1023001_1|833_1023001_2|833_1023101_1|278_1023101_2|208_1023201_1|69_1023201_2|104_1023301_1|34_1023301_2|52_1023401_1|17_1023401_2
A5: 20010080 | B5: 2500_1023001_1|1667_1023002_1|1250_1023003_1|833_1023101_1|556_1023102_1|417_1023103_1|208_1023201_1|139_1023202_1|104_1023203_1|104_1023301_1|69_1023302_1|52_1023303_1|52_1023401_1|35_1023402_1|26_1023403_1 | C5: =_xlfn.XLOOKUP(A5,$A$16:$A$222,$L$16:$L$222,B5) -> 2500_1023001_1|833_1023001_2|625_1023001_2|833_1023101_1|278_1023101_2|208_1023101_2|208_1023201_1|69_1023201_2|52_1023201_2|104_1023301_1|34_1023301_2|26_1023301_2|52_1023401_1|17_1023401_2|13_1023401_2
A6: 20010090 | B6: 250_1023001_1|1667_1023002_1|1250_1023003_1|83_1023101_1|556_1023102_1|417_1023103_1|20_1023201_1|139_1023202_1|104_1023203_1|10_1023301_1|69_1023302_1|52_1023303_1|5_1023401_1|35_1023402_1|26_1023403_1 | C6: =_xlfn.XLOOKUP(A6,$A$16:$A$222,$L$16:$L$222,B6) -> 250_1023001_1|833_1023001_2|625_1023001_2|83_1023101_1|278_1023101_2|208_1023101_2|20_1023201_1|69_1023201_2|52_1023201_2|10_1023301_1|34_1023301_2|26_1023301_2|5_1023401_1|17_1023401_2|13_1023401_2
A7: 20010100 | B7: 250_1023001_1|1667_1023002_1|1250_1023003_1|833_1023004_1|83_1023101_1|556_1023102_1|417_1023103_1|278_1023104_1|20_1023201_1|139_1023202_1|104_1023203_1|69_1023204_1|10_1023301_1|69_1023302_1|52_1023303_1|35_1023304_1|5_1023401_1|35_1023402_1|26_1023403_1|17_1023404_1 | C7: =_xlfn.XLOOKUP(A7,$A$16:$A$222,$L$16:$L$222,B7) -> 250_1023001_1|833_1023001_2|625_1023001_2|277_1023001_3|83_1023101_1|278_1023101_2|208_1023101_2|92_1023101_3|20_1023201_1|69_1023201_2|52_1023201_2|23_1023201_3|10_1023301_1|34_1023301_2|26_1023301_2
A8: 20010110 | B8: 250_1023001_1|166_1023002_1|1250_1023003_1|833_1023004_1|83_1023101_1|55_1023102_1|417_1023103_1|278_1023104_1|20_1023201_1|13_1023202_1|104_1023203_1|69_1023204_1|10_1023301_1|6_1023302_1|52_1023303_1|35_1023304_1|5_1023401_1|3_1023402_1|26_1023403_1|17_1023404_1 | C8: =_xlfn.XLOOKUP(A8,$A$16:$A$222,$L$16:$L$222,B8) -> 250_1023001_1|83_1023001_2|625_1023001_2|277_1023001_3|83_1023101_1|27_1023101_2|208_1023101_2|92_1023101_3|20_1023201_1|6_1023201_2|52_1023201_2|23_1023201_3|10_1023301_1|3_1023301_2|26_1023301_2
A9: 20010120 | B9: 250_1023001_1|166_1023002_1|1250_1023003_1|833_1023004_1|417_1023005_1|83_1023101_1|55_1023102_1|417_1023103_1|278_1023104_1|139_1023105_1|20_1023201_1|13_1023202_1|104_1023203_1|69_1023204_1|35_1023205_1|10_1023301_1|6_1023302_1|52_1023303_1|35_1023304_1|17_1023305_1|5_1023401_1|3_1023402_1|26_1023403_1|17_1023404_1|9_1023405_1 | C9: =_xlfn.XLOOKUP(A9,$A$16:$A$222,$L$16:$L$222,B9) -> 250_1023001_1|83_1023001_2|625_1023001_2|277_1023001_3|69_1023001_6|83_1023101_1|27_1023101_2|208_1023101_2|92_1023101_3|23_1023101_6|20_1023201_1|6_1023201_2|52_1023201_2|23_1023201_3|5_1023201_6
A10: 20010130 | B10: 250_1023001_1|166_1023002_1|125_1023003_1|833_1023004_1|417_1023005_1|83_1023101_1|55_1023102_1|41_1023103_1|278_1023104_1|139_1023105_1|20_1023201_1|13_1023202_1|10_1023203_1|69_1023204_1|35_1023205_1|10_1023301_1|6_1023302_1|5_1023303_1|35_1023304_1|17_1023305_1|5_1023401_1|3_1023402_1|2_1023403_1|17_1023404_1|9_1023405_1 | C10: =_xlfn.XLOOKUP(A10,$A$16:$A$222,$L$16:$L$222,B10) -> 250_1023001_1|83_1023001_2|62_1023001_2|277_1023001_3|69_1023001_6|83_1023101_1|27_1023101_2|20_1023101_2|92_1023101_3|23_1023101_6|20_1023201_1|6_1023201_2|5_1023201_2|23_1023201_3|5_1023201_6
A11: 20010140 | B11: 250_1023001_1|166_1023002_1|125_1023003_1|833_1023004_1|417_1023005_1|83_1023101_1|55_1023102_1|41_1023103_1|278_1023104_1|139_1023105_1|20_1023201_1|13_1023202_1|10_1023203_1|69_1023204_1|35_1023205_1|10_1023301_1|6_1023302_1|5_1023303_1|35_1023304_1|17_1023305_1|5_1023401_1|3_1023402_1|2_1023403_1|17_1023404_1|9_1023405_1 | C11: =_xlfn.XLOOKUP(A11,$A$16:$A$222,$L$16:$L$222,B11) -> 250_1023001_1|83_1023001_2|62_1023001_2|277_1023001_3|69_1023001_6|83_1023101_1|27_1023101_2|20_1023101_2|92_1023101_3|23_1023101_6|20_1023201_1|6_1023201_2|5_1023201_2|23_1023201_3|5_1023201_6
A12: 20010150 | B12: 250_1023001_1|166_1023002_1|125_1023003_1|83_1023004_1|417_1023005_1|83_1023101_1|55_1023102_1|41_1023103_1|27_1023104_1|139_1023105_1|20_1023201_1|13_1023202_1|10_1023203_1|6_1023204_1|35_1023205_1|10_1023301_1|6_1023302_1|5_1023303_1|3_1023304_1|17_1023305_1|5_1023401_1|3_1023402_1|2_1023403_1|1_1023404_1|9_1023405_1 | C12: =_xlfn.XLOOKUP(A12,$A$16:$A$222,$L$16:$L$222,B12) -> 250_1023001_1|83_1023001_2|62_1023001_2|27_1023001_3|69_1023001_6|83_1023101_1|27_1023101_2|20_1023101_2|9_1023101_3|23_1023101_6|20_1023201_1|6_1023201_2|5_1023201_2|2_1023201_3|5_1023201_6
A16: 20010060 | B16: 2500_1023001_1|1667_1023002_1|833_1023101_1|556_1023102_1|208_1023201_1|139_1023202_1|104_1023301_1|69_1023302_1|52_1023401_1|35_1023402_1 | L16: =_xlfn.TEXTJOIN("|",TRUE,L17:L26) -> 2500_1023001_1|833_1023001_2|833_1023101_1|278_1023101_2|208_1023201_1|69_1023201_2|104_1023301_1|34_1023301_2|52_1023401_1|17_1023401_2
B17: {=_xlfn.TEXTSPLIT(B16,,"|")} -> 2500_1023001_1 | C17: {=_xlfn.TEXTSPLIT(B17,"_",)} -> 2500 | D17: 1023001 | E17: 1 | F17: =_xlfn.XLOOKUP(VALUE(D17),Sheet2!$A$1:$A$25,Sheet2!$C$1:$C$25) -> 20 | G17: =VALUE(D17) -> 1023001 | H17: =_xlfn.XLOOKUP(G17,Sheet2!A:A,Sheet2!B:B) -> 1023001 | I17: =_xlfn.XLOOKUP(VALUE(H17),Sheet2!$A$1:$A$25,Sheet2!$C$1:$C$25) -> 20 | J17: =ROUNDUP(F17/I17,0) -> 1 | K17: =ROUNDDOWN(C17/J17,0) -> 2500 | L17: =_xlfn.TEXTJOIN("_",TRUE,K17,H17,J17) -> 2500_1023001_1
B18: 1667_1023002_1 | C18: {=_xlfn.TEXTSPLIT(B18,"_",)} -> 1667 | D18: 1023002 | E18: 1 | F18: =_xlfn.XLOOKUP(VALUE(D18),Sheet2!$A$1:$A$25,Sheet2!$C$1:$C$25) -> 30 | G18: =VALUE(D18) -> 1023002 | H18: =_xlfn.XLOOKUP(G18,Sheet2!A:A,Sheet2!B:B) -> 1023001 | I18: =_xlfn.XLOOKUP(VALUE(H18),Sheet2!$A$1:$A$25,Sheet2!$C$1:$C$25) -> 20 | J18: =ROUNDUP(F18/I18,0) -> 2 | K18: =ROUNDDOWN(C18/J18,0) -> 833 | L18: =_xlfn.TEXTJOIN("_",TRUE,K18,H18,J18) -> 833_1023001_2
B19: 833_1023101_1 | C19: {=_xlfn.TEXTSPLIT(B19,"_",)} -> 833 | D19: 1023101 | E19: 1 | F19: =_xlfn.XLOOKUP(VALUE(D19),Sheet2!$A$1:$A$25,Sheet2!$C$1:$C$25) -> 60 | G19: =VALUE(D19) -> 1023101 | H19: =_xlfn.XLOOKUP(G19,Sheet2!A:A,Sheet2!B:B) -> 1023101 | I19: =_xlfn.XLOOKUP(VALUE(H19),Sheet2!$A$1:$A$25,Sheet2!$C$1:$C$25) -> 60 | J19: =ROUNDUP(F19/I19,0) -> 1 | K19: =ROUNDDOWN(C19/J19,0) -> 833 | L19: =_xlfn.TEXTJOIN("_",TRUE,K19,H19,J19) -> 833_1023101_1
B20: 556_1023102_1 | C20: {=_xlfn.TEXTSPLIT(B20,"_",)} -> 556 | D20: 1023102 | E20: 1 | F20: =_xlfn.XLOOKUP(VALUE(D20),Sheet2!$A$1:$A$25,Sheet2!$C$1:$C$25) -> 90 | G20: =VALUE(D20) -> 1023102 | H20: =_xlfn.XLOOKUP(G20,Sheet2!A:A,Sheet2!B:B) -> 1023101 | I20: =_xlfn.XLOOKUP(VALUE(H20),Sheet2!$A$1:$A$25,Sheet2!$C$1:$C$25) -> 60 | J20: =ROUNDUP(F20/I20,0) -> 2 | K20: =ROUNDDOWN(C20/J20,0) -> 278 | L20: =_xlfn.TEXTJOIN("_",TRUE,K20,H20,J20) -> 278_1023101_2
B21: 208_1023201_1 | C21: {=_xlfn.TEXTSPLIT(B21,"_",)} -> 208 | D21: 1023201 | E21: 1 | F21: =_xlfn.XLOOKUP(VALUE(D21),Sheet2!$A$1:$A$25,Sheet2!$C$1:$C$25) -> 240 | G21: =VALUE(D21) -> 1023201 | H21: =_xlfn.XLOOKUP(G21,Sheet2!A:A,Sheet2!B:B) -> 1023201 | I21: =_xlfn.XLOOKUP(VALUE(H21),Sheet2!$A$1:$A$25,Sheet2!$C$1:$C$25) -> 240 | J21: =ROUNDUP(F21/I21,0) -> 1 | K21: =ROUNDDOWN(C21/J21,0) -> 208 | L21: =_xlfn.TEXTJOIN("_",TRUE,K21,H21,J21) -> 208_1023201_1
B22: 139_1023202_1 | C22: {=_xlfn.TEXTSPLIT(B22,"_",)} -> 139 | D22: 1023202 | E22: 1 | F22: =_xlfn.XLOOKUP(VALUE(D22),Sheet2!$A$1:$A$25,Sheet2!$C$1:$C$25) -> 360 | G22: =VALUE(D22) -> 1023202 | H22: =_xlfn.XLOOKUP(G22,Sheet2!A:A,Sheet2!B:B) -> 1023201 | I22: =_xlfn.XLOOKUP(VALUE(H22),Sheet2!$A$1:$A$25,Sheet2!$C$1:$C$25) -> 240 | J22: =ROUNDUP(F22/I22,0) -> 2 | K22: =ROUNDDOWN(C22/J22,0) -> 69 | L22: =_xlfn.TEXTJOIN("_",TRUE,K22,H22,J22) -> 69_1023201_2
B23: 104_1023301_1 | C23: {=_xlfn.TEXTSPLIT(B23,"_",)} -> 104 | D23: 1023301 | E23: 1 | F23: =_xlfn.XLOOKUP(VALUE(D23),Sheet2!$A$1:$A$25,Sheet2!$C$1:$C$25) -> 480 | G23: =VALUE(D23) -> 1023301 | H23: =_xlfn.XLOOKUP(G23,Sheet2!A:A,Sheet2!B:B) -> 1023301 | I23: =_xlfn.XLOOKUP(VALUE(H23),Sheet2!$A$1:$A$25,Sheet2!$C$1:$C$25) -> 480 | J23: =ROUNDUP(F23/I23,0) -> 1 | K23: =ROUNDDOWN(C23/J23,0) -> 104 | L23: =_xlfn.TEXTJOIN("_",TRUE,K23,H23,J23) -> 104_1023301_1
B24: 69_1023302_1 | C24: {=_xlfn.TEXTSPLIT(B24,"_",)} -> 69 | D24: 1023302 | E24: 1 | F24: =_xlfn.XLOOKUP(VALUE(D24),Sheet2!$A$1:$A$25,Sheet2!$C$1:$C$25) -> 720 | G24: =VALUE(D24) -> 1023302 | H24: =_xlfn.XLOOKUP(G24,Sheet2!A:A,Sheet2!B:B) -> 1023301 | I24: =_xlfn.XLOOKUP(VALUE(H24),Sheet2!$A$1:$A$25,Sheet2!$C$1:$C$25) -> 480 | J24: =ROUNDUP(F24/I24,0) -> 2 | K24: =ROUNDDOWN(C24/J24,0) -> 34 | L24: =_xlfn.TEXTJOIN("_",TRUE,K24,H24,J24) -> 34_1023301_2
B25: 52_1023401_1 | C25: {=_xlfn.TEXTSPLIT(B25,"_",)} -> 52 | D25: 1023401 | E25: 1 | F25: =_xlfn.XLOOKUP(VALUE(D25),Sheet2!$A$1:$A$25,Sheet2!$C$1:$C$25) -> 960 | G25: =VALUE(D25) -> 1023401 | H25: =_xlfn.XLOOKUP(G25,Sheet2!A:A,Sheet2!B:B) -> 1023401 | I25: =_xlfn.XLOOKUP(VALUE(H25),Sheet2!$A$1:$A$25,Sheet2!$C$1:$C$25) -> 960 | J25: =ROUNDUP(F25/I25,0) -> 1 | K25: =ROUNDDOWN(C25/J25,0) -> 52 | L25: =_xlfn.TEXTJOIN("_",TRUE,K25,H25,J25) -> 52_1023401_1
B26: 35_1023402_1 | C26: {=_xlfn.TEXTSPLIT(B26,"_",)} -> 35 | D26: 1023402 | E26: 1 | F26: =_xlfn.XLOOKUP(VALUE(D26),Sheet2!$A$1:$A$25,Sheet2!$C$1:$C$25) -> 1440 | G26: =VALUE(D26) -> 1023402 | H26: =_xlfn.XLOOKUP(G26,Sheet2!A:A,Sheet2!B:B) -> 1023401 | I26: =_xlfn.XLOOKUP(VALUE(H26),Sheet2!$A$1:$A$25,Sheet2!$C$1:$C$25) -> 960 | J26: =ROUNDUP(F26/I26,0) -> 2 | K26: =ROUNDDOWN(C26/J26,0) -> 17 | L26: =_xlfn.TEXTJOIN("_",TRUE,K26,H26,J26) -> 17_1023401_2
A29: 20010070 | B29: 2500_1023001_1|1667_1023002_1|833_1023101_1|556_1023102_1|208_1023201_1|139_1023202_1|104_1023301_1|69_1023302_1|52_1023401_1|35_1023402_1 | L29: =_xlfn.TEXTJOIN("|",TRUE,L30:L44) -> 2500_1023001_1|833_1023001_2|833_1023101_1|278_1023101_2|208_1023201_1|69_1023201_2|104_1023301_1|34_1023301_2|52_1023401_1|17_1023401_2
B30: {=_xlfn.TEXTSPLIT(B29,,"|")} -> 2500_1023001_1 | C30: {=_xlfn.TEXTSPLIT(B30,"_",)} -> 2500 | D30: 1023001 | E30: 1 | F30: =_xlfn.XLOOKUP(VALUE(D30),Sheet2!$A$1:$A$25,Sheet2!$C$1:$C$25) -> 20 | G30: =VALUE(D30) -> 1023001 | H30: =_xlfn.XLOOKUP(G30,Sheet2!A:A,Sheet2!B:B) -> 1023001 | I30: =_xlfn.XLOOKUP(VALUE(H30),Sheet2!$A$1:$A$25,Sheet2!$C$1:$C$25) -> 20 | J30: =ROUNDUP(F30/I30,0) -> 1 | K30: =ROUNDDOWN(C30/J30,0) -> 2500 | L30: =_xlfn.TEXTJOIN("_",TRUE,K30,H30,J30) -> 2500_1023001_1
B31: 1667_1023002_1 | C31: {=_xlfn.TEXTSPLIT(B31,"_",)} -> 1667 | D31: 1023002 | E31: 1 | F31: =_xlfn.XLOOKUP(VALUE(D31),Sheet2!$A$1:$A$25,Sheet2!$C$1:$C$25) -> 30 | G31: =VALUE(D31) -> 1023002 | H31: =_xlfn.XLOOKUP(G31,Sheet2!A:A,Sheet2!B:B) -> 1023001 | I31: =_xlfn.XLOOKUP(VALUE(H31),Sheet2!$A$1:$A$25,Sheet2!$C$1:$C$25) -> 20 | J31: =ROUNDUP(F31/I31,0) -> 2 | K31: =ROUNDDOWN(C31/J31,0) -> 833 | L31: =_xlfn.TEXTJOIN("_",TRUE,K31,H31,J31) -> 833_1023001_2
B32: 833_1023101_1 | C32: {=_xlfn.TEXTSPLIT(B32,"_",)} -> 833 | D32: 1023101 | E32: 1 | F32: =_xlfn.XLOOKUP(VALUE(D32),Sheet2!$A$1:$A$25,Sheet2!$C$1:$C$25) -> 60 | G32: =VALUE(D32) -> 1023101 | H32: =_xlfn.XLOOKUP(G32,Sheet2!A:A,Sheet2!B:B) -> 1023101 | I32: =_xlfn.XLOOKUP(VALUE(H32),Sheet2!$A$1:$A$25,Sheet2!$C$1:$C$25) -> 60 | J32: =ROUNDUP(F32/I32,0) -> 1 | K32: =ROUNDDOWN(C32/J32,0) -> 833 | L32: =_xlfn.TEXTJOIN("_",TRUE,K32,H32,J32) -> 833_1023101_1
B33: 556_1023102_1 | C33: {=_xlfn.TEXTSPLIT(B33,"_",)} -> 556 | D33: 1023102 | E33: 1 | F33: =_xlfn.XLOOKUP(VALUE(D33),Sheet2!$A$1:$A$25,Sheet2!$C$1:$C$25) -> 90 | G33: =VALUE(D33) -> 1023102 | H33: =_xlfn.XLOOKUP(G33,Sheet2!A:A,Sheet2!B:B) -> 1023101 | I33: =_xlfn.XLOOKUP(VALUE(H33),Sheet2!$A$1:$A$25,Sheet2!$C$1:$C$25) -> 60 | J33: =ROUNDUP(F33/I33,0) -> 2 | K33: =ROUNDDOWN(C33/J33,0) -> 278 | L33: =_xlfn.TEXTJOIN("_",TRUE,K33,H33,J33) -> 278_1023101_2
B34: 208_1023201_1 | C34: {=_xlfn.TEXTSPLIT(B34,"_",)} -> 208 | D34: 1023201 | E34: 1 | F34: =_xlfn.XLOOKUP(VALUE(D34),Sheet2!$A$1:$A$25,Sheet2!$C$1:$C$25) -> 240 | G34: =VALUE(D34) -> 1023201 | H34: =_xlfn.XLOOKUP(G34,Sheet2!A:A,Sheet2!B:B) -> 1023201 | I34: =_xlfn.XLOOKUP(VALUE(H34),Sheet2!$A$1:$A$25,Sheet2!$C$1:$C$25) -> 240 | J34: =ROUNDUP(F34/I34,0) -> 1 | K34: =ROUNDDOWN(C34/J34,0) -> 208 | L34: =_xlfn.TEXTJOIN("_",TRUE,K34,H34,J34) -> 208_1023201_1
B35: 139_1023202_1 | C35: {=_xlfn.TEXTSPLIT(B35,"_",)} -> 139 | D35: 1023202 | E35: 1 | F35: =_xlfn.XLOOKUP(VALUE(D35),Sheet2!$A$1:$A$25,Sheet2!$C$1:$C$25) -> 360 | G35: =VALUE(D35) -> 1023202 | H35: =_xlfn.XLOOKUP(G35,Sheet2!A:A,Sheet2!B:B) -> 1023201 | I35: =_xlfn.XLOOKUP(VALUE(H35),Sheet2!$A$1:$A$25,Sheet2!$C$1:$C$25) -> 240 | J35: =ROUNDUP(F35/I35,0) -> 2 | K35: =ROUNDDOWN(C35/J35,0) -> 69 | L35: =_xlfn.TEXTJOIN("_",TRUE,K35,H35,J35) -> 69_1023201_2
B36: 104_1023301_1 | C36: {=_xlfn.TEXTSPLIT(B36,"_",)} -> 104 | D36: 1023301 | E36: 1 | F36: =_xlfn.XLOOKUP(VALUE(D36),Sheet2!$A$1:$A$25,Sheet2!$C$1:$C$25) -> 480 | G36: =VALUE(D36) -> 1023301 | H36: =_xlfn.XLOOKUP(G36,Sheet2!A:A,Sheet2!B:B) -> 1023301 | I36: =_xlfn.XLOOKUP(VALUE(H36),Sheet2!$A$1:$A$25,Sheet2!$C$1:$C$25) -> 480 | J36: =ROUNDUP(F36/I36,0) -> 1 | K36: =ROUNDDOWN(C36/J36,0) -> 104 | L36: =_xlfn.TEXTJOIN("_",TRUE,K36,H36,J36) -> 104_1023301_1
B37: 69_1023302_1 | C37: {=_xlfn.TEXTSPLIT(B37,"_",)} -> 69 | D37: 1023302 | E37: 1 | F37: =_xlfn.XLOOKUP(VALUE(D37),Sheet2!$A$1:$A$25,Sheet2!$C$1:$C$25) -> 720 | G37: =VALUE(D37) -> 1023302 | H37: =_xlfn.XLOOKUP(G37,Sheet2!A:A,Sheet2!B:B) -> 1023301 | I37: =_xlfn.XLOOKUP(VALUE(H37),Sheet2!$A$1:$A$25,Sheet2!$C$1:$C$25) -> 480 | J37: =ROUNDUP(F37/I37,0) -> 2 | K37: =ROUNDDOWN(C37/J37,0) -> 34 | L37: =_xlfn.TEXTJOIN("_",TRUE,K37,H37,J37) -> 34_1023301_2
B38: 52_1023401_1 | C38: {=_xlfn.TEXTSPLIT(B38,"_",)} -> 52 | D38: 1023401 | E38: 1 | F38: =_xlfn.XLOOKUP(VALUE(D38),Sheet2!$A$1:$A$25,Sheet2!$C$1:$C$25) -> 960 | G38: =VALUE(D38) -> 1023401 | H38: =_xlfn.XLOOKUP(G38,Sheet2!A:A,Sheet2!B:B) -> 1023401 | I38: =_xlfn.XLOOKUP(VALUE(H38),Sheet2!$A$1:$A$25,Sheet2!$C$1:$C$25) -> 960 | J38: =ROUNDUP(F38/I38,0) -> 1 | K38: =ROUNDDOWN(C38/J38,0) -> 52 | L38: =_xlfn.TEXTJOIN("_",TRUE,K38,H38,J38) -> 52_1023401_1
B39: 35_1023402_1 | C39: {=_xlfn.TEXTSPLIT(B39,"_",)} -> 35 | D39: 1023402 | E39: 1 | F39: =_xlfn.XLOOKUP(VALUE(D39),Sheet2!$A$1:$A$25,Sheet2!$C$1:$C$25) -> 1440 | G39: =VALUE(D39) -> 1023402 | H39: =_xlfn.XLOOKUP(G39,Sheet2!A:A,Sheet2!B:B) -> 1023401 | I39: =_xlfn.XLOOKUP(VALUE(H39),Sheet2!$A$1:$A$25,Sheet2!$C$1:$C$25) -> 960 | J39: =ROUNDUP(F39/I39,0) -> 2 | K39: =ROUNDDOWN(C39/J39,0) -> 17 | L39: =_xlfn.TEXTJOIN("_",TRUE,K39,H39,J39) -> 17_1023401_2
A48: 20010080 | B48: =_xlfn.XLOOKUP(A48,$A$1:$A$12,$B$1:$B$12) -> 2500_1023001_1|1667_1023002_1|1250_1023003_1|833_1023101_1|556_1023102_1|417_1023103_1|208_1023201_1|139_1023202_1|104_1023203_1|104_1023301_1|69_1023302_1|52_1023303_1|52_1023401_1|35_1023402_1|26_1023403_1 | L48: =_xlfn.TEXTJOIN("|",TRUE,L49:L63) -> 2500_1023001_1|833_1023001_2|625_1023001_2|833_1023101_1|278_1023101_2|208_1023101_2|208_1023201_1|69_1023201_2|52_1023201_2|104_1023301_1|34_1023301_2|26_1023301_2|52_1023401_1|17_1023401_2|13_1023401_2
B49: {=_xlfn.TEXTSPLIT(B48,,"|")} -> 2500_1023001_1 | C49: {=_xlfn.TEXTSPLIT(B49,"_",)} -> 2500 | D49: 1023001 | E49: 1 | F49: =_xlfn.XLOOKUP(VALUE(D49),Sheet2!$A$1:$A$25,Sheet2!$C$1:$C$25) -> 20 | G49: =VALUE(D49) -> 1023001 | H49: =_xlfn.XLOOKUP(G49,Sheet2!A:A,Sheet2!B:B) -> 1023001 | I49: =_xlfn.XLOOKUP(VALUE(H49),Sheet2!$A$1:$A$25,Sheet2!$C$1:$C$25) -> 20 | J49: =ROUNDUP(F49/I49,0) -> 1 | K49: =ROUNDDOWN(C49/J49,0) -> 2500 | L49: =_xlfn.TEXTJOIN("_",TRUE,K49,H49,J49) -> 2500_1023001_1
B50: 1667_1023002_1 | C50: {=_xlfn.TEXTSPLIT(B50,"_",)} -> 1667 | D50: 1023002 | E50: 1 | F50: =_xlfn.XLOOKUP(VALUE(D50),Sheet2!$A$1:$A$25,Sheet2!$C$1:$C$25) -> 30 | G50: =VALUE(D50) -> 1023002 | H50: =_xlfn.XLOOKUP(G50,Sheet2!A:A,Sheet2!B:B) -> 1023001 | I50: =_xlfn.XLOOKUP(VALUE(H50),Sheet2!$A$1:$A$25,Sheet2!$C$1:$C$25) -> 20 | J50: =ROUNDUP(F50/I50,0) -> 2 | K50: =ROUNDDOWN(C50/J50,0) -> 833 | L50: =_xlfn.TEXTJOIN("_",TRUE,K50,H50,J50) -> 833_1023001_2
B51: 1250_1023003_1 | C51: {=_xlfn.TEXTSPLIT(B51,"_",)} -> 1250 | D51: 1023003 | E51: 1 | F51: =_xlfn.XLOOKUP(VALUE(D51),Sheet2!$A$1:$A$25,Sheet2!$C$1:$C$25) -> 40 | G51: =VALUE(D51) -> 1023003 | H51: =_xlfn.XLOOKUP(G51,Sheet2!A:A,Sheet2!B:B) -> 1023001 | I51: =_xlfn.XLOOKUP(VALUE(H51),Sheet2!$A$1:$A$25,Sheet2!$C$1:$C$25) -> 20 | J51: =ROUNDUP(F51/I51,0) -> 2 | K51: =ROUNDDOWN(C51/J51,0) -> 625 | L51: =_xlfn.TEXTJOIN("_",TRUE,K51,H51,J51) -> 625_1023001_2
B52: 833_1023101_1 | C52: {=_xlfn.TEXTSPLIT(B52,"_",)} -> 833 | D52: 1023101 | E52: 1 | F52: =_xlfn.XLOOKUP(VALUE(D52),Sheet2!$A$1:$A$25,Sheet2!$C$1:$C$25) -> 60 | G52: =VALUE(D52) -> 1023101 | H52: =_xlfn.XLOOKUP(G52,Sheet2!A:A,Sheet2!B:B) -> 1023101 | I52: =_xlfn.XLOOKUP(VALUE(H52),Sheet2!$A$1:$A$25,Sheet2!$C$1:$C$25) -> 60 | J52: =ROUNDUP(F52/I52,0) -> 1 | K52: =ROUNDDOWN(C52/J52,0) -> 833 | L52: =_xlfn.TEXTJOIN("_",TRUE,K52,H52,J52) -> 833_1023101_1
B53: 556_1023102_1 | C53: {=_xlfn.TEXTSPLIT(B53,"_",)} -> 556 | D53: 1023102 | E53: 1 | F53: =_xlfn.XLOOKUP(VALUE(D53),Sheet2!$A$1:$A$25,Sheet2!$C$1:$C$25) -> 90 | G53: =VALUE(D53) -> 1023102 | H53: =_xlfn.XLOOKUP(G53,Sheet2!A:A,Sheet2!B:B) -> 1023101 | I53: =_xlfn.XLOOKUP(VALUE(H53),Sheet2!$A$1:$A$25,Sheet2!$C$1:$C$25) -> 60 | J53: =ROUNDUP(F53/I53,0) -> 2 | K53: =ROUNDDOWN(C53/J53,0) -> 278 | L53: =_xlfn.TEXTJOIN("_",TRUE,K53,H53,J53) -> 278_1023101_2
...

Sheet Sheet1 (2)
A1: 20020001 | B1: 4450_1023001_4|2960_1023101_2|1480_1023201_1|740_1023301_1|370_1023401_1 | C1: =_xlfn.XLOOKUP(A1,$A$16:$A$222,$L$16:$L$222,B1) -> 4450_1023001_4|2960_1023101_2|1480_1023201_1|740_1023301_1|370_1023401_1
A2: 20020002 | B2: 4450_1023002_4|2960_1023102_2|1480_1023202_1|740_1023302_1|370_1023402_1 | C2: =_xlfn.XLOOKUP(A2,$A$16:$A$222,$L$16:$L$222,B2) -> 4450_1023001_6|2960_1023101_3|987_1023201_2|494_1023301_2|247_1023401_2
A3: 20020003 | B3: 4450_1023003_4|2960_1023103_2|1480_1023203_1|740_1023303_1|370_1023403_1 | C3: =_xlfn.XLOOKUP(A3,$A$16:$A$222,$L$16:$L$222,B3) -> 4450_1023001_8|2960_1023101_4|1480_1023201_2|740_1023301_2|370_1023401_2
A4: 20020004 | B4: 4450_1023004_4|2960_1023104_2|1480_1023204_1|740_1023304_1|370_1023404_1 | C4: =_xlfn.XLOOKUP(A4,$A$16:$A$222,$L$16:$L$222,B4) -> 4450_1023001_12|2960_1023101_6|1480_1023201_3|740_1023301_3|370_1023401_3
A5: 20020005 | B5: 4450_1023005_4|2960_1023105_2|1480_1023205_1|740_1023305_1|370_1023405_1 | C5: =_xlfn.XLOOKUP(A5,$A$16:$A$222,$L$16:$L$222,B5) -> 4450_1023001_24|2960_1023101_12|1480_1023201_6|740_1023301_6|370_1023401_6
A6: 20020011 | B6: 4450_1023001_8|2960_1023101_4|1480_1023201_2|740_1023301_2|370_1023401_2 | C6: =_xlfn.XLOOKUP(A6,$A$16:$A$222,$L$16:$L$222,B6) -> 4450_1023001_8|2960_1023101_4|1480_1023201_2|740_1023301_2|370_1023401_2
A7: 20020012 | B7: 4450_1023002_8|2960_1023102_4|1480_1023202_2|740_1023302_2|370_1023402_2 | C7: =_xlfn.XLOOKUP(A7,$A$16:$A$222,$L$16:$L$222,B7) -> 4450_1023001_12|2960_1023101_6|1480_1023201_3|740_1023301_3|370_1023401_3
A8: 20020013 | B8: 4450_1023003_8|2960_1023103_4|1480_1023203_2|740_1023303_2|370_1023403_2 | C8: =_xlfn.XLOOKUP(A8,$A$16:$A$222,$L$16:$L$222,B8) -> 4450_1023001_16|2960_1023101_8|1480_1023201_4|740_1023301_4|370_1023401_4
A9: 20020014 | B9: 4450_1023004_8|2960_1023104_4|1480_1023204_2|740_1023304_2|370_1023404_2 | C9: =_xlfn.XLOOKUP(A9,$A$16:$A$222,$L$16:$L$222,B9) -> 4450_1023001_24|2960_1023101_12|1480_1023201_6|740_1023301_6|370_1023401_6
A10: 20020015 | B10: 4450_1023005_8|2960_1023105_4|1480_1023205_2|740_1023305_2|370_1023405_2 | C10: =_xlfn.XLOOKUP(A10,$A$16:$A$222,$L$16:$L$222,B10) -> 4450_1023001_48|2960_1023101_24|1480_1023201_12|740_1023301_12|370_1023401_12
E15: 原数量 | F15: 总价 | G15: 原道具 | H15: 新道具 | I15: 单价 | J15: 新数量
A16: 20020001 | B16: =_xlfn.XLOOKUP(A16,$A$1:$A$12,$B$1:$B$12) -> 4450_1023001_4|2960_1023101_2|1480_1023201_1|740_1023301_1|370_1023401_1 | L16: =_xlfn.TEXTJOIN("|",TRUE,L17:L26) -> 4450_1023001_4|2960_1023101_2|1480_1023201_1|740_1023301_1|370_1023401_1
B17: {=_xlfn.TEXTSPLIT(B16,,"|")} -> 4450_1023001_4 | C17: {=_xlfn.TEXTSPLIT(B17,"_",)} -> 4450 | D17: 1023001 | E17: 4 | F17: =_xlfn.XLOOKUP(VALUE(D17),Sheet2!$A$1:$A$25,Sheet2!$C$1:$C$25)*E17 -> 80 | G17: =VALUE(D17) -> 1023001 | H17: =_xlfn.XLOOKUP(G17,Sheet2!A:A,Sheet2!B:B) -> 1023001 | I17: =_xlfn.XLOOKUP(VALUE(H17),Sheet2!$A$1:$A$25,Sheet2!$C$1:$C$25) -> 20 | J17: =ROUNDUP(IF(H17=G17,E17,F17/I17),0) -> 4 | K17: =ROUNDUP(IF(H17=G17,C17,C17),0) -> 4450 | L17: =_xlfn.TEXTJOIN("_",TRUE,K17,H17,J17) -> 4450_1023001_4
B18: 2960_1023101_2 | C18: {=_xlfn.TEXTSPLIT(B18,"_",)} -> 2960 | D18: 1023101 | E18: 2 | F18: =_xlfn.XLOOKUP(VALUE(D18),Sheet2!$A$1:$A$25,Sheet2!$C$1:$C$25)*E18 -> 120 | G18: =VALUE(D18) -> 1023101 | H18: =_xlfn.XLOOKUP(G18,Sheet2!A:A,Sheet2!B:B) -> 1023101 | I18: =_xlfn.XLOOKUP(VALUE(H18),Sheet2!$A$1:$A$25,Sheet2!$C$1:$C$25) -> 60 | J18: =ROUNDUP(IF(H18=G18,E18,F18/I18),0) -> 2 | K18: =ROUNDUP(IF(H18=G18,C18,C18),0) -> 2960 | L18: =_xlfn.TEXTJOIN("_",TRUE,K18,H18,J18) -> 2960_1023101_2
B19: 1480_1023201_1 | C19: {=_xlfn.TEXTSPLIT(B19,"_",)} -> 1480 | D19: 1023201 | E19: 1 | F19: =_xlfn.XLOOKUP(VALUE(D19),Sheet2!$A$1:$A$25,Sheet2!$C$1:$C$25)*E19 -> 240 | G19: =VALUE(D19) -> 1023201 | H19: =_xlfn.XLOOKUP(G19,Sheet2!A:A,Sheet2!B:B) -> 1023201 | I19: =_xlfn.XLOOKUP(VALUE(H19),Sheet2!$A$1:$A$25,Sheet2!$C$1:$C$25) -> 240 | J19: =ROUNDUP(IF(H19=G19,E19,F19/I19),0) -> 1 | K19: =ROUNDUP(IF(H19=G19,C19,C19),0) -> 1480 | L19: =_xlfn.TEXTJOIN("_",TRUE,K19,H19,J19) -> 1480_1023201_1
B20: 740_1023301_1 | C20: {=_xlfn.TEXTSPLIT(B20,"_",)} -> 740 | D20: 1023301 | E20: 1 | F20: =_xlfn.XLOOKUP(VALUE(D20),Sheet2!$A$1:$A$25,Sheet2!$C$1:$C$25)*E20 -> 480 | G20: =VALUE(D20) -> 1023301 | H20: =_xlfn.XLOOKUP(G20,Sheet2!A:A,Sheet2!B:B) -> 1023301 | I20: =_xlfn.XLOOKUP(VALUE(H20),Sheet2!$A$1:$A$25,Sheet2!$C$1:$C$25) -> 480 | J20: =ROUNDUP(IF(H20=G20,E20,F20/I20),0) -> 1 | K20: =ROUNDUP(IF(H20=G20,C20,C20),0) -> 740 | L20: =_xlfn.TEXTJOIN("_",TRUE,K20,H20,J20) -> 740_1023301_1
B21: 370_1023401_1 | C21: {=_xlfn.TEXTSPLIT(B21,"_",)} -> 370 | D21: 1023401 | E21: 1 | F21: =_xlfn.XLOOKUP(VALUE(D21),Sheet2!$A$1:$A$25,Sheet2!$C$1:$C$25)*E21 -> 960 | G21: =VALUE(D21) -> 1023401 | H21: =_xlfn.XLOOKUP(G21,Sheet2!A:A,Sheet2!B:B) -> 1023401 | I21: =_xlfn.XLOOKUP(VALUE(H21),Sheet2!$A$1:$A$25,Sheet2!$C$1:$C$25) -> 960 | J21: =ROUNDUP(IF(H21=G21,E21,F21/I21),0) -> 1 | K21: =ROUNDUP(IF(H21=G21,C21,C21),0) -> 370 | L21: =_xlfn.TEXTJOIN("_",TRUE,K21,H21,J21) -> 370_1023401_1
A29: 20020002 | B29: =_xlfn.XLOOKUP(A29,$A$1:$A$12,$B$1:$B$12) -> 4450_1023002_4|2960_1023102_2|1480_1023202_1|740_1023302_1|370_1023402_1 | L29: =_xlfn.TEXTJOIN("|",TRUE,L30:L44) -> 4450_1023001_6|2960_1023101_3|987_1023201_2|494_1023301_2|247_1023401_2
B30: {=_xlfn.TEXTSPLIT(B29,,"|")} -> 4450_1023002_4 | C30: {=_xlfn.TEXTSPLIT(B30,"_",)} -> 4450 | D30: 1023002 | E30: 4 | F30: =_xlfn.XLOOKUP(VALUE(D30),Sheet2!$A$1:$A$25,Sheet2!$C$1:$C$25)*E30 -> 120 | G30: =VALUE(D30) -> 1023002 | H30: =_xlfn.XLOOKUP(G30,Sheet2!A:A,Sheet2!B:B) -> 1023001 | I30: =_xlfn.XLOOKUP(VALUE(H30),Sheet2!$A$1:$A$25,Sheet2!$C$1:$C$25) -> 20 | J30: =ROUNDUP(IF(H30=G30,E30,F30/I30),2) -> 6 | K30: =ROUNDUP(IF(H30=G30,C30,C30),0) -> 4450 | L30: =_xlfn.TEXTJOIN("_",TRUE,K30,H30,J30) -> 4450_1023001_6
B31: 2960_1023102_2 | C31: {=_xlfn.TEXTSPLIT(B31,"_",)} -> 2960 | D31: 1023102 | E31: 2 | F31: =_xlfn.XLOOKUP(VALUE(D31),Sheet2!$A$1:$A$25,Sheet2!$C$1:$C$25)*E31 -> 180 | G31: =VALUE(D31) -> 1023102 | H31: =_xlfn.XLOOKUP(G31,Sheet2!A:A,Sheet2!B:B) -> 1023101 | I31: =_xlfn.XLOOKUP(VALUE(H31),Sheet2!$A$1:$A$25,Sheet2!$C$1:$C$25) -> 60 | J31: =ROUNDUP(IF(H31=G31,E31,F31/I31),2) -> 3 | K31: =ROUNDUP(IF(H31=G31,C31,C31),0) -> 2960 | L31: =_xlfn.TEXTJOIN("_",TRUE,K31,H31,J31) -> 2960_1023101_3
B32: 1480_1023202_1 | C32: {=_xlfn.TEXTSPLIT(B32,"_",)} -> 1480 | D32: 1023202 | E32: 1 | F32: =_xlfn.XLOOKUP(VALUE(D32),Sheet2!$A$1:$A$25,Sheet2!$C$1:$C$25)*E32 -> 360 | G32: =VALUE(D32) -> 1023202 | H32: =_xlfn.XLOOKUP(G32,Sheet2!A:A,Sheet2!B:B) -> 1023201 | I32: =_xlfn.XLOOKUP(VALUE(H32),Sheet2!$A$1:$A$25,Sheet2!$C$1:$C$25) -> 240 | J32: =ROUNDUP(IF(H32=G32,E32,F32/I32),2) -> 1.5 | K32: =ROUNDUP(IF(H32=G32,C32,C32/N32),0) -> 987 | L32: =_xlfn.TEXTJOIN("_",TRUE,K32,H32,O32) -> 987_1023201_2 | N32: 1.5 | O32: =ROUNDUP(J32,0) -> 2
B33: 740_1023302_1 | C33: {=_xlfn.TEXTSPLIT(B33,"_",)} -> 740 | D33: 1023302 | E33: 1 | F33: =_xlfn.XLOOKUP(VALUE(D33),Sheet2!$A$1:$A$25,Sheet2!$C$1:$C$25)*E33 -> 720 | G33: =VALUE(D33) -> 1023302 | H33: =_xlfn.XLOOKUP(G33,Sheet2!A:A,Sheet2!B:B) -> 1023301 | I33: =_xlfn.XLOOKUP(VALUE(H33),Sheet2!$A$1:$A$25,Sheet2!$C$1:$C$25) -> 480 | J33: =ROUNDUP(IF(H33=G33,E33,F33/I33),2) -> 1.5 | K33: =ROUNDUP(IF(H33=G33,C33,C33/N33),0) -> 494 | L33: =_xlfn.TEXTJOIN("_",TRUE,K33,H33,O33) -> 494_1023301_2 | N33: 1.5 | O33: =ROUNDUP(J33,0) -> 2
B34: 370_1023402_1 | C34: {=_xlfn.TEXTSPLIT(B34,"_",)} -> 370 | D34: 1023402 | E34: 1 | F34: =_xlfn.XLOOKUP(VALUE(D34),Sheet2!$A$1:$A$25,Sheet2!$C$1:$C$25)*E34 -> 1440 | G34: =VALUE(D34) -> 1023402 | H34: =_xlfn.XLOOKUP(G34,Sheet2!A:A,Sheet2!B:B) -> 1023401 | I34: =_xlfn.XLOOKUP(VALUE(H34),Sheet2!$A$1:$A$25,Sheet2!$C$1:$C$25) -> 960 | J34: =ROUNDUP(IF(H34=G34,E34,F34/I34),2) -> 1.5 | K34: =ROUNDUP(IF(H34=G34,C34,C34/N34),0) -> 247 | L34: =_xlfn.TEXTJOIN("_",TRUE,K34,H34,O34) -> 247_1023401_2 | N34: 1.5 | O34: =ROUNDUP(J34,0) -> 2
A48: 20020003 | B48: =_xlfn.XLOOKUP(A48,$A$1:$A$12,$B$1:$B$12) -> 4450_1023003_4|2960_1023103_2|1480_1023203_1|740_1023303_1|370_1023403_1 | L48: =_xlfn.TEXTJOIN("|",TRUE,L49:L63) -> 4450_1023001_8|2960_1023101_4|1480_1023201_2|740_1023301_2|370_1023401_2
B49: {=_xlfn.TEXTSPLIT(B48,,"|")} -> 4450_1023003_4 | C49: {=_xlfn.TEXTSPLIT(B49,"_",)} -> 4450 | D49: 1023003 | E49: 4 | F49: =_xlfn.XLOOKUP(VALUE(D49),Sheet2!$A$1:$A$25,Sheet2!$C$1:$C$25)*E49 -> 160 | G49: =VALUE(D49) -> 1023003 | H49: =_xlfn.XLOOKUP(G49,Sheet2!A:A,Sheet2!B:B) -> 1023001 | I49: =_xlfn.XLOOKUP(VALUE(H49),Sheet2!$A$1:$A$25,Sheet2!$C$1:$C$25) -> 20 | J49: =ROUNDUP(IF(H49=G49,E49,F49/I49),2) -> 8 | K49: =ROUNDUP(IF(H49=G49,C49,C49),0) -> 4450 | L49: =_xlfn.TEXTJOIN("_",TRUE,K49,H49,J49) -> 4450_1023001_8
B50: 2960_1023103_2 | C50: {=_xlfn.TEXTSPLIT(B50,"_",)} -> 2960 | D50: 1023103 | E50: 2 | F50: =_xlfn.XLOOKUP(VALUE(D50),Sheet2!$A$1:$A$25,Sheet2!$C$1:$C$25)*E50 -> 240 | G50: =VALUE(D50) -> 1023103 | H50: =_xlfn.XLOOKUP(G50,Sheet2!A:A,Sheet2!B:B) -> 1023101 | I50: =_xlfn.XLOOKUP(VALUE(H50),Sheet2!$A$1:$A$25,Sheet2!$C$1:$C$25) -> 60 | J50: =ROUNDUP(IF(H50=G50,E50,F50/I50),2) -> 4 | K50: =ROUNDUP(IF(H50=G50,C50,C50),0) -> 2960 | L50: =_xlfn.TEXTJOIN("_",TRUE,K50,H50,J50) -> 2960_1023101_4
B51: 1480_1023203_1 | C51: {=_xlfn.TEXTSPLIT(B51,"_",)} -> 1480 | D51: 1023203 | E51: 1 | F51: =_xlfn.XLOOKUP(VALUE(D51),Sheet2!$A$1:$A$25,Sheet2!$C$1:$C$25)*E51 -> 480 | G51: =VALUE(D51) -> 1023203 | H51: =_xlfn.XLOOKUP(G51,Sheet2!A:A,Sheet2!B:B) -> 1023201 | I51: =_xlfn.XLOOKUP(VALUE(H51),Sheet2!$A$1:$A$25,Sheet2!$C$1:$C$25) -> 240 | J51: =ROUNDUP(IF(H51=G51,E51,F51/I51),2) -> 2 | K51: =ROUNDUP(IF(H51=G51,C51,C51),0) -> 1480 | L51: =_xlfn.TEXTJOIN("_",TRUE,K51,H51,J51) -> 1480_1023201_2
B52: 740_1023303_1 | C52: {=_xlfn.TEXTSPLIT(B52,"_",)} -> 740 | D52: 1023303 | E52: 1 | F52: =_xlfn.XLOOKUP(VALUE(D52),Sheet2!$A$1:$A$25,Sheet2!$C$1:$C$25)*E52 -> 960 | G52: =VALUE(D52) -> 1023303 | H52: =_xlfn.XLOOKUP(G52,Sheet2!A:A,Sheet2!B:B) -> 1023301 | I52: =_xlfn.XLOOKUP(VALUE(H52),Sheet2!$A$1:$A$25,Sheet2!$C$1:$C$25) -> 480 | J52: =ROUNDUP(IF(H52=G52,E52,F52/I52),2) -> 2 | K52: =ROUNDUP(IF(H52=G52,C52,C52),0) -> 740 | L52: =_xlfn.TEXTJOIN("_",TRUE,K52,H52,J52) -> 740_1023301_2
B53: 370_1023403_1 | C53: {=_xlfn.TEXTSPLIT(B53,"_",)} -> 370 | D53: 1023403 | E53: 1 | F53: =_xlfn.XLOOKUP(VALUE(D53),Sheet2!$A$1:$A$25,Sheet2!$C$1:$C$25)*E53 -> 1920 | G53: =VALUE(D53) -> 1023403 | H53: =_xlfn.XLOOKUP(G53,Sheet2!A:A,Sheet2!B:B) -> 1023401 | I53: =_xlfn.XLOOKUP(VALUE(H53),Sheet2!$A$1:$A$25,Sheet2!$C$1:$C$25) -> 960 | J53: =ROUNDUP(IF(H53=G53,E53,F53/I53),2) -> 2 | K53: =ROUNDUP(IF(H53=G53,C53,C53),0) -> 370 | L53: =_xlfn.TEXTJOIN("_",TRUE,K53,H53,J53) -> 370_1023401_2
A66: 20020004 | B66: =_xlfn.XLOOKUP(A66,$A$1:$A$12,$B$1:$B$12) -> 4450_1023004_4|2960_1023104_2|1480_1023204_1|740_1023304_1|370_1023404_1 | L66: =_xlfn.TEXTJOIN("|",TRUE,L67:L81) -> 4450_1023001_12|2960_1023101_6|1480_1023201_3|740_1023301_3|370_1023401_3
B67: {=_xlfn.TEXTSPLIT(B66,,"|")} -> 4450_1023004_4 | C67: {=_xlfn.TEXTSPLIT(B67,"_",)} -> 4450 | D67: 1023004 | E67: 4 | F67: =_xlfn.XLOOKUP(VALUE(D67),Sheet2!$A$1:$A$25,Sheet2!$C$1:$C$25)*E67 -> 240 | G67: =VALUE(D67) -> 1023004 | H67: =_xlfn.XLOOKUP(G67,Sheet2!A:A,Sheet2!B:B) -> 1023001 | I67: =_xlfn.XLOOKUP(VALUE(H67),Sheet2!$A$1:$A$25,Sheet2!$C$1:$C$25) -> 20 | J67: =ROUNDUP(IF(H67=G67,E67,F67/I67),2) -> 12 | K67: =ROUNDUP(IF(H67=G67,C67,C67),0) -> 4450 | L67: =_xlfn.TEXTJOIN("_",TRUE,K67,H67,J67) -> 4450_1023001_12
B68: 2960_1023104_2 | C68: {=_xlfn.TEXTSPLIT(B68,"_",)} -> 2960 | D68: 1023104 | E68: 2 | F68: =_xlfn.XLOOKUP(VALUE(D68),Sheet2!$A$1:$A$25,Sheet2!$C$1:$C$25)*E68 -> 360 | G68: =VALUE(D68) -> 1023104 | H68: =_xlfn.XLOOKUP(G68,Sheet2!A:A,Sheet2!B:B) -> 1023101 | I68: =_xlfn.XLOOKUP(VALUE(H68),Sheet2!$A$1:$A$25,Sheet2!$C$1:$C$25) -> 60 | J68: =ROUNDUP(IF(H68=G68,E68,F68/I68),2) -> 6 | K68: =ROUNDUP(IF(H68=G68,C68,C68),0) -> 2960 | L68: =_xlfn.TEXTJOIN("_",TRUE,K68,H68,J68) -> 2960_1023101_6
B69: 1480_1023204_1 | C69: {=_xlfn.TEXTSPLIT(B69,"_",)} -> 1480 | D69: 1023204 | E69: 1 | F69: =_xlfn.XLOOKUP(VALUE(D69),Sheet2!$A$1:$A$25,Sheet2!$C$1:$C$25)*E69 -> 720 | G69: =VALUE(D69) -> 1023204 | H69: =_xlfn.XLOOKUP(G69,Sheet2!A:A,Sheet2!B:B) -> 1023201 | I69: =_xlfn.XLOOKUP(VALUE(H69),Sheet2!$A$1:$A$25,Sheet2!$C$1:$C$25) -> 240 | J69: =ROUNDUP(IF(H69=G69,E69,F69/I69),2) -> 3 | K69: =ROUNDUP(IF(H69=G69,C69,C69),0) -> 1480 | L69: =_xlfn.TEXTJOIN("_",TRUE,K69,H69,J69) -> 1480_1023201_3
B70: 740_1023304_1 | C70: {=_xlfn.TEXTSPLIT(B70,"_",)} -> 740 | D70: 1023304 | E70: 1 | F70: =_xlfn.XLOOKUP(VALUE(D70),Sheet2!$A$1:$A$25,Sheet2!$C$1:$C$25)*E70 -> 1440 | G70: =VALUE(D70) -> 1023304 | H70: =_xlfn.XLOOKUP(G70,Sheet2!A:A,Sheet2!B:B) -> 1023301 | I70: =_xlfn.XLOOKUP(VALUE(H70),Sheet2!$A$1:$A$25,Sheet2!$C$1:$C$25) -> 480 | J70: =ROUNDUP(IF(H70=G70,E70,F70/I70),2) -> 3 | K70: =ROUNDUP(IF(H70=G70,C70,C70),0) -> 740 | L70: =_xlfn.TEXTJOIN("_",TRUE,K70,H70,J70) -> 740_1023301_3
B71: 370_1023404_1 | C71: {=_xlfn.TEXTSPLIT(B71,"_",)} -> 370 | D71: 1023404 | E71: 1 | F71: =_xlfn.XLOOKUP(VALUE(D71),Sheet2!$A$1:$A$25,Sheet2!$C$1:$C$25)*E71 -> 2880 | G71: =VALUE(D71) -> 1023404 | H71: =_xlfn.XLOOKUP(G71,Sheet2!A:A,Sheet2!B:B) -> 1023401 | I71: =_xlfn.XLOOKUP(VALUE(H71),Sheet2!$A$1:$A$25,Sheet2!$C$1:$C$25) -> 960 | J71: =ROUNDUP(IF(H71=G71,E71,F71/I71),2) -> 3 | K71: =ROUNDUP(IF(H71=G71,C71,C71),0) -> 370 | L71: =_xlfn.TEXTJOIN("_",TRUE,K71,H71,J71) -> 370_1023401_3
A84: 20020005 | B84: =_xlfn.XLOOKUP(A84,$A$1:$A$12,$B$1:$B$12) -> 4450_1023005_4|2960_1023105_2|1480_1023205_1|740_1023305_1|370_1023405_1 | L84: =_xlfn.TEXTJOIN("|",TRUE,L85:L99) -> 4450_1023001_24|2960_1023101_12|1480_1023201_6|740_1023301_6|370_1023401_6
B85: {=_xlfn.TEXTSPLIT(B84,,"|")} -> 4450_1023005_4 | C85: {=_xlfn.TEXTSPLIT(B85,"_",)} -> 4450 | D85: 1023005 | E85: 4 | F85: =_xlfn.XLOOKUP(VALUE(D85),Sheet2!$A$1:$A$25,Sheet2!$C$1:$C$25)*E85 -> 480 | G85: =VALUE(D85) -> 1023005 | H85: =_xlfn.XLOOKUP(G85,Sheet2!A:A,Sheet2!B:B) -> 1023001 | I85: =_xlfn.XLOOKUP(VALUE(H85),Sheet2!$A$1:$A$25,Sheet2!$C$1:$C$25) -> 20 | J85: =ROUNDUP(IF(H85=G85,E85,F85/I85),2) -> 24 | K85: =ROUNDUP(IF(H85=G85,C85,C85),0) -> 4450 | L85: =_xlfn.TEXTJOIN("_",TRUE,K85,H85,J85) -> 4450_1023001_24
B86: 2960_1023105_2 | C86: {=_xlfn.TEXTSPLIT(B86,"_",)} -> 2960 | D86: 1023105 | E86: 2 | F86: =_xlfn.XLOOKUP(VALUE(D86),Sheet2!$A$1:$A$25,Sheet2!$C$1:$C$25)*E86 -> 720 | G86: =VALUE(D86) -> 1023105 | H86: =_xlfn.XLOOKUP(G86,Sheet2!A:A,Sheet2!B:B) -> 1023101 | I86: =_xlfn.XLOOKUP(VALUE(H86),Sheet2!$A$1:$A$25,Sheet2!$C$1:$C$25) -> 60 | J86: =ROUNDUP(IF(H86=G86,E86,F86/I86),2) -> 12 | K86: =ROUNDUP(IF(H86=G86,C86,C86),0) -> 2960 | L86: =_xlfn.TEXTJOIN("_",TRUE,K86,H86,J86) -> 2960_1023101_12
B87: 1480_1023205_1 | C87: {=_xlfn.TEXTSPLIT(B87,"_",)} -> 1480 | D87: 1023205 | E87: 1 | F87: =_xlfn.XLOOKUP(VALUE(D87),Sheet2!$A$1:$A$25,Sheet2!$C$1:$C$25)*E87 -> 1440 | G87: =VALUE(D87) -> 1023205 | H87: =_xlfn.XLOOKUP(G87,Sheet2!A:A,Sheet2!B:B) -> 1023201 | I87: =_xlfn.XLOOKUP(VALUE(H87),Sheet2!$A$1:$A$25,Sheet2!$C$1:$C$25) -> 240 | J87: =ROUNDUP(IF(H87=G87,E87,F87/I87),2) -> 6 | K87: =ROUNDUP(IF(H87=G87,C87,C87),0) -> 1480 | L87: =_xlfn.TEXTJOIN("_",TRUE,K87,H87,J87) -> 1480_1023201_6
B88: 740_1023305_1 | C88: {=_xlfn.TEXTSPLIT(B88,"_",)} -> 740 | D88: 1023305 | E88: 1 | F88: =_xlfn.XLOOKUP(VALUE(D88),Sheet2!$A$1:$A$25,Sheet2!$C$1:$C$25)*E88 -> 2880 | G88: =VALUE(D88) -> 1023305 | H88: =_xlfn.XLOOKUP(G88,Sheet2!A:A,Sheet2!B:B) -> 1023301 | I88: =_xlfn.XLOOKUP(VALUE(H88),Sheet2!$A$1:$A$25,Sheet2!$C$1:$C$25) -> 480 | J88: =ROUNDUP(IF(H88=G88,E88,F88/I88),2) -> 6 | K88: =ROUNDUP(IF(H88=G88,C88,C88),0) -> 740 | L88: =_xlfn.TEXTJOIN("_",TRUE,K88,H88,J88) -> 740_1023301_6
...

Sheet Sheet2
A1: 1023001 | B1: =A1 -> 1023001 | C1: 20
A2: 1023002 | B2: =A1 -> 1023001 | C2: 30
A3: 1023003 | B3: =A1 -> 1023001 | C3: 40
A4: 1023004 | B4: =A1 -> 1023001 | C4: 60
A5: 1023005 | B5: =A1 -> 1023001 | C5: 120
A6: 1023101 | B6: =A6 -> 1023101 | C6: 60
A7: 1023102 | B7: =A6 -> 1023101 | C7: 90
A8: 1023103 | B8: =A6 -> 1023101 | C8: 120
A9: 1023104 | B9: =A6 -> 1023101 | C9: 180
A10: 1023105 | B10: =A6 -> 1023101 | C10: 360
A11: 1023201 | B11: =A11 -> 1023201 | C11: 240
A12: 1023202 | B12: =A11 -> 1023201 | C12: 360
A13: 1023203 | B13: =A11 -> 1023201 | C13: 480
A14: 1023204 | B14: =A11 -> 1023201 | C14: 720
A15: 1023205 | B15: =A11 -> 1023201 | C15: 1440
A16: 1023301 | B16: =A16 -> 1023301 | C16: 480
A17: 1023302 | B17: =A16 -> 1023301 | C17: 720
A18: 1023303 | B18: =A16 -> 1023301 | C18: 960
A19: 1023304 | B19: =A16 -> 1023301 | C19: 1440
A20: 1023305 | B20: =A16 -> 1023301 | C20: 2880
A21: 1023401 | B21: =A21 -> 1023401 | C21: 960
A22: 1023402 | B22: =A21 -> 1023401 | C22: 1440
A23: 1023403 | B23: =A21 -> 1023401 | C23: 1920
A24: 1023404 | B24: =A21 -> 1023401 | C24: 2880
A25: 1023405 | B25: =A21 -> 1023401 | C25: 5760
